Workbook
Name AHPAlternativeNames: Tablo2[Alternative names]
Name AHPCriteriaNames: Tablo2[Criteria names]
Name BWNames: Tablo19[Attribute names]
Name FPCAlternativeNames: Tablo213[Alternative names]
Name GridAlternativeNames: Tablo215[Alternative names]
Name GridCriteriaNames: Tablo215[Criteria names]
Name Names_of_Categories: FPCPage!#REF!
Name Names_of_FPCCategories: Tablo213[Category names]
Name AHPAlternativeNames: [1]!Tablo2[Alternative names]
Name AHPAlternativeNamesD: [1]Depot!$K$3:$K$12
Name AHPCategoryNames: [1]AHPPage!$H$6:$H$10
Name AHPCriteriaNames: [1]!Tablo2[Criteria names]
Name AHPCriteriaNamesD: [1]Depot!$J$3:$J$12
Name AHPMaxs: [1]AHPOutput!$B$3004:$SG$3004
Name AHPMeans: [1]AHPOutput!$B$3002:$SG$3002
Name AHPMedians: [1]AHPOutput!$B$3006:$SG$3006
Name AHPMins: [1]AHPOutput!$B$3003:$SG$3003
Name AHPStDevs: [1]AHPOutput!$B$3005:$SG$3005
Name BWNames: [1]!Tablo19[Attribute names]
Name Category_numbers: [1]Depot!$L$22:$L$31
Name FPCAlternativeNames: [1]!Tablo213[Alternative names]
Name FPCAlternativeNamesD: [1]Depot!$H$3:$H$12
Name FPCCategoryNames: [1]FPCPage!$H$5:$H$12
Name FPCCategoryNamesD: [1]Depot!$I$3:$I$7
Name FPCData: [1]FPCData!$A$2:$AS$2002
Name FPCMaxs: [1]FPCOutput!$B$3004:$SB$3004
Name FPCMeans: [1]FPCOutput!$B$3002:$SB$3002
Name FPCMedians: [1]FPCOutput!$B$3006:$SB$3006
Name FPCMins: [1]FPCOutput!$B$3003:$SB$3003
Name FPCSecsay: [1]FPCPage!$C$5
Name FPCStDevs: [1]FPCOutput!$B$3005:$SB$3005
Name GridAlternativeNames: [1]!Tablo215[Alternative names]
Name GridAlternativeNamesD: [1]Depot!$N$3:$N$12
Name GridCategoryNames: [1]GridPage!$I$5:$I$6
Name GridCategoryNamesD: [1]Depot!$O$3:$O$7
Name GridCriteriaNames: [1]!Tablo215[Criteria names]
Name GridCriteriaNamesD: [1]Depot!$M$3:$M$12
Name GridData: [1]GridData!$A$2:$DF$2001
Name GridKrSay: [1]GridPage!$C$5
Name GridMaxs: [1]GridOutput!$B$3004:$SH$3004
Name GridMeans: [1]GridOutput!$B$3002:$SH$3002
Name GridMedians: [1]GridOutput!$B$3006:$SH$3006
Name GridMins: [1]GridOutput!$B$3003:$SH$3003
Name GridSecSay: [1]GridPage!$C$6
Name GridStDevs: [1]GridOutput!$B$3005:$SH$3005
Name Names_of_AHPcategoriesD: [1]Depot!$L$3:$L$12
Name Names_of_BWcategories: [1]MaxDiffPage!$G$5:$G$34
Name Names_of_Categories: [1]FPCPage!#REF!
Name Names_of_FPCCategories: [1]!Tablo213[Category names]
Name secsay10: [1]GridOutput!$JR$2
Name secsay3: [1]GridOutput!$GL$2
Name secsay4: [1]GridOutput!$GX$2
Name secsay5: [1]GridOutput!$HJ$2
Name secsay6: [1]GridOutput!$HV$2
Name secsay7: [1]GridOutput!$IH$2
Name secsay8: [1]GridOutput!$IT$2
Name secsay9: [1]GridOutput!$JF$2
Name AHPAlternativeNames: [1]!Tablo2[Alternative names]
Name AHPAlternativeNamesD: [1]Depot!$K$3:$K$12
Name AHPCategoryNames: [1]AHPPage!$H$6:$H$10

Sheet Hiyerarsi_Indeks
B2: AHP Hiyerarşi Çalışma Sayfaları
B4: Bu dosyada 1 ana blok, 4 alt grup ve 13 gösterge matrisi düzeyinde olmak üzere toplam 18 AHP çalışma sayfası vardır.
B6: Düzey | C6: Bağlı Olduğu Yapı | D6: Karşılaştırma Grubu | E6: İçerik | F6: Karşılaştırılan Parametre Sayısı sayısı | G6: Sayfa adı
A7: 1 | B7: Ana blok | C7: TSGS | D7: Ana Bloklar | E7: Ana bloklar | F7: 4 | G7: ESG_FO_AnaBlok
A8: 2 | B8: Alt Grup | C8: Ana Bloklar | D8: Çevre | E8: Alt gruplar | F8: 4 | G8: E_AltGruplar
A9: 3 | B9: Gösterge | C9: Çevre | D9: Enerji ve Emisyonlar | E9: Göstergeler | F9: 7 | G9: E_EnerjiEmis
A10: 4 | B10: Gösterge | C10: Çevre | D10: Su Yönetimi | E10: Göstergeler | F10: 7 | G10: E_AltGruplar
A11: 5 | B11: Gösterge | C11: Çevre | D11: Biyoçeşitlilik ve Toprak | E11: Göstergeler | F11: 5 | G11: E_AltGruplar
A12: 6 | B12: Gösterge | C12: Çevre | D12: Atıklar ve Kimyasallar | E12: Göstergeler | F12: 7 | G12: E_AltGruplar
A13: 7 | B13: Alt Grup | C13: Ana Bloklar | D13: Sosyal | E13: Alt Gruplar | F13: 3 | G13: E_AtikKimya
A14: 8 | B14: Gösterge | C14: Sosyal | D14: İşgücü/İstihdam | E14: Göstergeler | F14: 9 | G14: S_AltGruplar
A15: 9 | B15: Gösterge | C15: Sosyal | D15: Çalışma Koşullaru | E15: Göstergeler | F15: 8 | G15: S_IsgucuIst
A16: 10 | B16: Gösterge | C16: Sosyal | D16: Toplum / Kişisel Koruma | E16: Göstergeler | F16: 3 | G16: S_AltGruplar
A17: 11 | B17: Alt Grup | C17: Ana Bloklar | D17: Yönetişim | E17: Alt Gruplar | F17: 2 | G17: S_CalismaKos
A18: 12 | B18: Gösterge | C18: Yönetişim | D18: Uyum ve Politika | E18: Göstergeler | F18: 12 | G18: S_AltGruplar
... A24: 18 | B24: Gösterge | C24: Finans ve Operasyon | D24: Bitkisel Üretim | E24: Göstergeler | F24: 4 | G24: FO_AltGruplar

Sheet Kullanim_Notu
B2: Uyarlama ve kullanım notu
B4: Kapsam | C4: Bu çalışma kitabı, Osman Hoca’nın AHP şablonu korunarak E–S–G–FO ana bloklarının ilk düzey ikili karşılaştırmasını uygulamak üzere hazırlanmıştır.
B5: Giriş | C5: Uzman/karar verici, ESG_FO_AnaBlok sayfasındaki sarı hücrelere üst üçgendeki altı karşılaştırma değerini girecektir: E-S, E-G, E-FO, S-G, S-FO, G-FO.
B6: Ölçek | C6: Saaty 1–9 ölçeği kullanılmalıdır. Bir blok diğerinden daha az önemliyse 1/2, 1/3, …, 1/9 gibi ters değerler girilmelidir.
B7: Otomatik hesap | C7: Alt üçgen, sütun toplamları, normalize matris, yerel ağırlıklar, λmax, CI, RI ve CR otomatik hesaplanır.
B8: Yorum | C8: CR ≤ 0,10 genel pratik tutarlılık kontrolü olarak kabul edilir. CR yüksek çıkarsa ikili karşılaştırmalar gerekçeleriyle yeniden değerlendirilmelidir.
B9: Sonraki aşama | C9: Aynı mantıkla E, S, G ve FO alt grupları; daha sonra her alt grubun göstergeleri için ayrı matrisler oluşturulacaktır.
B10: Önemli ayrım | C10: Bu dosyada henüz uzman görüşü veya gerçek ikili karşılaştırma değeri girilmemiştir. Sarı hücreler boş bırakılmıştır; ağırlıklar veri girildikten sonra oluşacaktır.
B12: Düzeltme | C12: λmax hesabı Excel uyumluluğu için SUMPRODUCT yerine açık çarpım toplamı ile kurulmuştur.
B15: Kapsamlı sürüm | C15: Hiyerarsi_Indeks sayfasından tüm ana blok, alt grup ve gösterge AHP sayfalarına geçebilirsiniz.

Sheet ESG_FO_Makale
B2: AHP Ana Blok Ağırlıklandırması: E–S–G–FO
B4: Amaç | C4: Tarım işletmelerinin bütünleşik sürdürülebilirlik performansının değerlendirilmesi
B5: Karşılaştırma düzeyi | C5: Ana bloklar: Çevre (E), Sosyal (S), Yönetişim (G), Finans ve Operasyon (FO)
B7: 1. İkili karşılaştırma matrisi – uzman/karar verici giriş alanı
C8: E – Çevre | D8: S – Sosyal | E8: G – Yönetişim | F8: FO – Finans ve Operasyon | H8: Giriş açıklaması
B9: E – Çevre | C9: 1 | D9: 5 | E9: 6 | F9: 9 | H9: Sarı hücrelere yalnızca Saaty ölçeğinde 1, 2, …, 9 veya bunların karşılık değerlerini giriniz. Yeşil hücreler otomatik ters değerlerdir.
B10: S – Sosyal | C10: =IFERROR(1/D9,"") | D10: 1 | E10: 2 | F10: 4
B11: G – Yönetişim | C11: =IFERROR(1/E9,"") | D11: =IFERROR(1/E10,"") | E11: 1 | F11: 2
B12: FO – Finans ve Operasyon | C12: =IFERROR(1/F9,"") | D12: =IFERROR(1/F10,"") | E12: =IFERROR(1/F11,"") | F12: 1
B15: 2. Normalize matris ve yerel ağırlıklar
C16: E – Çevre | D16: S – Sosyal | E16: G – Yönetişim | F16: FO – Finans ve Operasyon | G16: Yerel ağırlık
B17: E – Çevre | C17: =IFERROR(C9/C$21,"") | D17: =IFERROR(D9/D$21,"") | E17: =IFERROR(E9/E$21,"") | F17: =IFERROR(F9/F$21,"") | G17: =IFERROR(AVERAGE(C17:F17),"")
B18: S – Sosyal | C18: =IFERROR(C10/C$21,"") | D18: =IFERROR(D10/D$21,"") | E18: =IFERROR(E10/E$21,"") | F18: =IFERROR(F10/F$21,"") | G18: =IFERROR(AVERAGE(C18:F18),"")
B19: G – Yönetişim | C19: =IFERROR(C11/C$21,"") | D19: =IFERROR(D11/D$21,"") | E19: =IFERROR(E11/E$21,"") | F19: =IFERROR(F11/F$21,"") | G19: =IFERROR(AVERAGE(C19:F19),"")
B20: FO – Finans ve Operasyon | C20: =IFERROR(C12/C$21,"") | D20: =IFERROR(D12/D$21,"") | E20: =IFERROR(E12/E$21,"") | F20: =IFERROR(F12/F$21,"") | G20: =IFERROR(AVERAGE(C20:F20),"")
B21: Sütun toplamı | C21: =SUM(C9:C12) | D21: =SUM(D9:D12) | E21: =SUM(E9:E12) | F21: =SUM(F9:F12)
B23: Ağırlık toplamı | G23: =SUM(G17:G20)
B25: 3. Tutarlılık analizi
B26: λmax | G26: =C21*G17+D21*G18+E21*G19+F21*G20
B27: CI | G27: =IFERROR((G26-4)/(4-1),"")
B28: RI (n=4) | G28: 0.9
B29: CR | G29: =IFERROR(G27/G28,"")
B30: Karar | G30: =IF(COUNT(D9:F11)<6,"Veri bekleniyor",IF(G29<=0.1,"Tutarlı (CR ≤ 0,10)","Gözden geçirilmeli (CR > 0,10)"))
B32: Not: Bu sayfa yalnızca E–S–G–FO ana bloklarının ağırlıklandırılması içindir. Alt grup ve gösterge matrisleri ayrı sayfalarda kurulacaktır.
B35: Düzeltme notu | C35: λmax formülü satır-sütun boyut uyumsuzluğu nedeniyle #DEĞER! üretebiliyordu; açık çarpım formülüyle düzeltildi.

Sheet ESG_FO_AnaBlok
B2: AHP Ana Blok Ağırlıklandırması: E–S–G–FO
B4: Amaç | C4: Tarım işletmelerinin bütünleşik sürdürülebilirlik performansının değerlendirilmesi
B5: Karşılaştırma düzeyi | C5: Ana bloklar: Çevre (E), Sosyal (S), Yönetişim (G), Finans ve Operasyon (FO)
B7: 1. İkili karşılaştırma matrisi – uzman/karar verici giriş alanı
C8: E – Çevre | D8: S – Sosyal | E8: G – Yönetişim | F8: FO – Finans ve Operasyon | H8: Giriş açıklaması
B9: E – Çevre | C9: 1 | D9: 3 | E9: 4 | F9: 7 | H9: Sarı hücrelere yalnızca Saaty ölçeğinde 1, 2, …, 9 veya bunların karşılık değerlerini giriniz. Yeşil hücreler otomatik ters değerlerdir.
B10: S – Sosyal | C10: =IFERROR(1/D9,"") | D10: 1 | E10: 2 | F10: 4
B11: G – Yönetişim | C11: =IFERROR(1/E9,"") | D11: =IFERROR(1/E10,"") | E11: 1 | F11: 2
B12: FO – Finans ve Operasyon | C12: =IFERROR(1/F9,"") | D12: =IFERROR(1/F10,"") | E12: =IFERROR(1/F11,"") | F12: 1
B15: 2. Normalize matris ve yerel ağırlıklar
C16: E – Çevre | D16: S – Sosyal | E16: G – Yönetişim | F16: FO – Finans ve Operasyon | G16: Yerel ağırlık
B17: E – Çevre | C17: =IFERROR(C9/C$21,"") | D17: =IFERROR(D9/D$21,"") | E17: =IFERROR(E9/E$21,"") | F17: =IFERROR(F9/F$21,"") | G17: =IFERROR(AVERAGE(C17:F17),"")
B18: S – Sosyal | C18: =IFERROR(C10/C$21,"") | D18: =IFERROR(D10/D$21,"") | E18: =IFERROR(E10/E$21,"") | F18: =IFERROR(F10/F$21,"") | G18: =IFERROR(AVERAGE(C18:F18),"")
B19: G – Yönetişim | C19: =IFERROR(C11/C$21,"") | D19: =IFERROR(D11/D$21,"") | E19: =IFERROR(E11/E$21,"") | F19: =IFERROR(F11/F$21,"") | G19: =IFERROR(AVERAGE(C19:F19),"")
B20: FO – Finans ve Operasyon | C20: =IFERROR(C12/C$21,"") | D20: =IFERROR(D12/D$21,"") | E20: =IFERROR(E12/E$21,"") | F20: =IFERROR(F12/F$21,"") | G20: =IFERROR(AVERAGE(C20:F20),"")
B21: Sütun toplamı | C21: =SUM(C9:C12) | D21: =SUM(D9:D12) | E21: =SUM(E9:E12) | F21: =SUM(F9:F12)
B23: Ağırlık toplamı | G23: =SUM(G17:G20)
B25: 3. Tutarlılık analizi
B26: λmax | G26: =C21*G17+D21*G18+E21*G19+F21*G20
B27: CI | G27: =IFERROR((G26-4)/(4-1),"")
B28: RI (n=4) | G28: 0.9
B29: CR | G29: =IFERROR(G27/G28,"")
B30: Karar | G30: =IF(COUNT(D9:F11)<6,"Veri bekleniyor",IF(G29<=0.1,"Tutarlı (CR ≤ 0,10)","Gözden geçirilmeli (CR > 0,10)"))
B32: Not: Bu sayfa yalnızca E–S–G–FO ana bloklarının ağırlıklandırılması içindir. Alt grup ve gösterge matrisleri ayrı sayfalarda kurulacaktır.
B35: Düzeltme notu | C35: λmax formülü satır-sütun boyut uyumsuzluğu nedeniyle #DEĞER! üretebiliyordu; açık çarpım formülüyle düzeltildi.

Sheet E_AltGruplar
B2: Çevre Ana Bloğu Alt Grupları AHP
B4: Karşılaştırma düzeyi | C4: Çevre ana bloğu alt grup karşılaştırması
B6: 1. İkili karşılaştırma matrisi – sarı hücrelere giriş yapınız
C7: Enerji ve Emisyonlar | D7: Su Yönetimi | E7: Biyoçeşitlilik ve Toprak | F7: Atıklar ve Kimyasallar | G7: Yerel ağırlık | H7: Giriş açıklaması
B8: Enerji ve Emisyonlar | C8: 1 | D8: 0.5 | E8: 0.33 | F8: 2 | H8: Sarı hücrelere Saaty ölçeğinde 1–9 veya ters değerleri giriniz. Yeşil hücreler otomatik ters değerlerdir.
B9: Su Yönetimi | C9: =IFERROR(1/D8,"") | D9: 1 | E9: 0.5 | F9: 4
B10: Biyoçeşitlilik ve Toprak | C10: =IFERROR(1/E8,"") | D10: =IFERROR(1/E9,"") | E10: 1 | F10: 6
B11: Atıklar ve Kimyasallar | C11: =IFERROR(1/F8,"") | D11: =IFERROR(1/F9,"") | E11: =IFERROR(1/F10,"") | F11: 1
B14: 2. Normalize matris ve yerel ağırlıklar
C15: Enerji ve Emisyonlar | D15: Su Yönetimi | E15: Biyoçeşitlilik ve Toprak | F15: Atıklar ve Kimyasallar | G15: Yerel ağırlık
B16: Enerji ve Emisyonlar | C16: =IFERROR(C8/C$20,"") | D16: =IFERROR(D8/D$20,"") | E16: =IFERROR(E8/E$20,"") | F16: =IFERROR(F8/F$20,"") | G16: =IFERROR(AVERAGE(C16:F16),"")
B17: Su Yönetimi | C17: =IFERROR(C9/C$20,"") | D17: =IFERROR(D9/D$20,"") | E17: =IFERROR(E9/E$20,"") | F17: =IFERROR(F9/F$20,"") | G17: =IFERROR(AVERAGE(C17:F17),"")
B18: Biyoçeşitlilik ve Toprak | C18: =IFERROR(C10/C$20,"") | D18: =IFERROR(D10/D$20,"") | E18: =IFERROR(E10/E$20,"") | F18: =IFERROR(F10/F$20,"") | G18: =IFERROR(AVERAGE(C18:F18),"")
B19: Atıklar ve Kimyasallar | C19: =IFERROR(C11/C$20,"") | D19: =IFERROR(D11/D$20,"") | E19: =IFERROR(E11/E$20,"") | F19: =IFERROR(F11/F$20,"") | G19: =IFERROR(AVERAGE(C19:F19),"")
B20: Sütun toplamı | C20: =SUM(C8:C11) | D20: =SUM(D8:D11) | E20: =SUM(E8:E11) | F20: =SUM(F8:F11)
B22: Ağırlık toplamı | G22: =SUM(G16:G19)
B24: 3. Tutarlılık analizi
B25: λmax | G25: =C20*G16+D20*G17+E20*G18+F20*G19
B26: CI | G26: =IFERROR((G25-4)/(4-1),"")
B27: RI (n=4) | G27: 0.9
B28: CR | G28: =IFERROR(G26/G27,"")
B29: Karar | G29: =IF(COUNT(D8,E8,F8,E9,F9,F10)<6,"Veri bekleniyor",IF(G28<=0.1,"Tutarlı (CR ≤ 0,10)","Gözden geçirilmeli (CR > 0,10)"))

Sheet E_EnerjiEmis
B2: Çevre → Enerji ve Emisyonlar Göstergeleri AHP
B4: Karşılaştırma düzeyi | C4: Çevre → Enerji ve Emisyonlar
B6: 1. İkili karşılaştırma matrisi – sarı hücrelere giriş yapınız
C7: E-01 Enerji Kaynağı (Fosil, Elektrik, Yenilenebilir) | D7: E-02 Yıllık toplam enerji tüketimi (kWh/litre) | E7: E-03 Enerji verimliliği artırma uygulamaları | F7: E-04 Yenilenebilir enerji kullanım oranı (%) | G7: E-05 Karbon ayak izi hesaplama durumu | H7: E-06 İş makineleri yakıt verimliliği | I7: E-07 Lojistik ve dağıtım ağı mesafesi (300 km kriteri) | K7: Giriş açıklaması
B8: E-01 Enerji Kaynağı (Fosil, Elektrik, Yenilenebilir) | C8: 1 | D8: 2 | E8: 3 | F8: 3 | G8: 4 | H8: 2 | I8: 4 | K8: Sarı hücrelere Saaty ölçeğinde 1–9 veya ters değerleri giriniz. Yeşil hücreler otomatik ters değerlerdir.
B9: E-02 Yıllık toplam enerji tüketimi (kWh/litre) | C9: =IFERROR(1/D8,"") | D9: 1 | E9: 2 | F9: 3 | G9: 5 | H9: 2 | I9: 3
B10: E-03 Enerji verimliliği artırma uygulamaları | C10: =IFERROR(1/E8,"") | D10: =IFERROR(1/E9,"") | E10: 1 | F10: 0.5 | G10: 3 | H10: 2 | I10: =3
B11: E-04 Yenilenebilir enerji kullanım oranı (%) | C11: =IFERROR(1/F8,"") | D11: =IFERROR(1/F9,"") | E11: =IFERROR(1/F10,"") | F11: 1 | G11: =4 | H11: =2 | I11: =2
B12: E-05 Karbon ayak izi hesaplama durumu | C12: =IFERROR(1/G8,"") | D12: =IFERROR(1/G9,"") | E12: =IFERROR(1/G10,"") | F12: =IFERROR(1/G11,"") | G12: 1 | H12: =1/4 | I12: =1/4
B13: E-06 İş makineleri yakıt verimliliği | C13: =IFERROR(1/H8,"") | D13: =IFERROR(1/H9,"") | E13: =IFERROR(1/H10,"") | F13: =IFERROR(1/H11,"") | G13: =IFERROR(1/H12,"") | H13: 1 | I13: 4
B14: E-07 Lojistik ve dağıtım ağı mesafesi (300 km kriteri) | C14: =IFERROR(1/I8,"") | D14: =IFERROR(1/I9,"") | E14: =IFERROR(1/I10,"") | F14: =IFERROR(1/I11,"") | G14: =IFERROR(1/I12,"") | H14: =IFERROR(1/I13,"") | I14: 1
B17: 2. Normalize matris ve yerel ağırlıklar
C18: E-01 Enerji Kaynağı (Fosil, Elektrik, Yenilenebilir) | D18: E-02 Yıllık toplam enerji tüketimi (kWh/litre) | E18: E-03 Enerji verimliliği artırma uygulamaları | F18: E-04 Yenilenebilir enerji kullanım oranı (%) | G18: E-05 Karbon ayak izi hesaplama durumu | H18: E-06 İş makineleri yakıt verimliliği | I18: E-07 Lojistik ve dağıtım ağı mesafesi (300 km kriteri) | J18: Yerel ağırlık
B19: E-01 Enerji Kaynağı (Fosil, Elektrik, Yenilenebilir) | C19: =IFERROR(C8/C$26,"") | D19: =IFERROR(D8/D$26,"") | E19: =IFERROR(E8/E$26,"") | F19: =IFERROR(F8/F$26,"") | G19: =IFERROR(G8/G$26,"") | H19: =IFERROR(H8/H$26,"") | I19: =IFERROR(I8/I$26,"") | J19: =IFERROR(AVERAGE(C19:I19),"")
B20: E-02 Yıllık toplam enerji tüketimi (kWh/litre) | C20: =IFERROR(C9/C$26,"") | D20: =IFERROR(D9/D$26,"") | E20: =IFERROR(E9/E$26,"") | F20: =IFERROR(F9/F$26,"") | G20: =IFERROR(G9/G$26,"") | H20: =IFERROR(H9/H$26,"") | I20: =IFERROR(I9/I$26,"") | J20: =IFERROR(AVERAGE(C20:I20),"")
B21: E-03 Enerji verimliliği artırma uygulamaları | C21: =IFERROR(C10/C$26,"") | D21: =IFERROR(D10/D$26,"") | E21: =IFERROR(E10/E$26,"") | F21: =IFERROR(F10/F$26,"") | G21: =IFERROR(G10/G$26,"") | H21: =IFERROR(H10/H$26,"") | I21: =IFERROR(I10/I$26,"") | J21: =IFERROR(AVERAGE(C21:I21),"")
B22: E-04 Yenilenebilir enerji kullanım oranı (%) | C22: =IFERROR(C11/C$26,"") | D22: =IFERROR(D11/D$26,"") | E22: =IFERROR(E11/E$26,"") | F22: =IFERROR(F11/F$26,"") | G22: =IFERROR(G11/G$26,"") | H22: =IFERROR(H11/H$26,"") | I22: =IFERROR(I11/I$26,"") | J22: =IFERROR(AVERAGE(C22:I22),"")
B23: E-05 Karbon ayak izi hesaplama durumu | C23: =IFERROR(C12/C$26,"") | D23: =IFERROR(D12/D$26,"") | E23: =IFERROR(E12/E$26,"") | F23: =IFERROR(F12/F$26,"") | G23: =IFERROR(G12/G$26,"") | H23: =IFERROR(H12/H$26,"") | I23: =IFERROR(I12/I$26,"") | J23: =IFERROR(AVERAGE(C23:I23),"")
B24: E-06 İş makineleri yakıt verimliliği | C24: =IFERROR(C13/C$26,"") | D24: =IFERROR(D13/D$26,"") | E24: =IFERROR(E13/E$26,"") | F24: =IFERROR(F13/F$26,"") | G24: =IFERROR(G13/G$26,"") | H24: =IFERROR(H13/H$26,"") | I24: =IFERROR(I13/I$26,"") | J24: =IFERROR(AVERAGE(C24:I24),"")
B25: E-07 Lojistik ve dağıtım ağı mesafesi (300 km kriteri) | C25: =IFERROR(C14/C$26,"") | D25: =IFERROR(D14/D$26,"") | E25: =IFERROR(E14/E$26,"") | F25: =IFERROR(F14/F$26,"") | G25: =IFERROR(G14/G$26,"") | H25: =IFERROR(H14/H$26,"") | I25: =IFERROR(I14/I$26,"") | J25: =IFERROR(AVERAGE(C25:I25),"")
B26: Sütun toplamı | C26: =SUM(C8:C14) | D26: =SUM(D8:D14) | E26: =SUM(E8:E14) | F26: =SUM(F8:F14) | G26: =SUM(G8:G14) | H26: =SUM(H8:H14) | I26: =SUM(I8:I14)
B28: Ağırlık toplamı | J28: =SUM(J19:J25)
B30: 3. Tutarlılık analizi
B31: λmax | J31: =C26*J19+D26*J20+E26*J21+F26*J22+G26*J23+H26*J24+I26*J25
B32: CI | J32: =IFERROR((J31-7)/(7-1),"")
B33: RI (n=7) | J33: 1.32
B34: CR | J34: =IFERROR(J32/J33,"")
B35: Karar | J35: =IF(COUNT(D8,E8,F8,G8,H8,I8,E9,F9,G9,H9,I9,F10,G10,H10,I10,G11,H11,I11,H12,I12,I13)<21,"Veri bekleniyor",IF(J34<=0.1,"Tutarlı (CR ≤ 0,10)","Gözden geçirilmeli (CR > 0,10)"))

Sheet E_SuYonetim
B2: Çevre → Su Yönetimi Göstergeleri AHP
B4: Karşılaştırma düzeyi | C4: Çevre → Su Yönetimi
B6: 1. İkili karşılaştırma matrisi – sarı hücrelere giriş yapınız
C7: E-08 Toplam yıllık su çekimi/tüketimi | D7: E-09 Su kaynakları (Yeraltı, Yüzey, Şebeke) | E7: E-10 Toplam sulanan arazi varlığı (da) | F7: E-11 Su tasarrufu teknikleri (Damla/Yağmurlama) | G7: E-12 Atık su bertaraf ve arıtma yöntemleri | H7: E-13 Sulu Tarım oranı | I7: E-14 Yıllık Yağış | K7: Giriş açıklaması
B8: E-08 Toplam yıllık su çekimi/tüketimi | C8: 1 | D8: 1 | E8: 3 | F8: 3 | G8: 6 | H8: 4 | I8: 6 | K8: Sarı hücrelere Saaty ölçeğinde 1–9 veya ters değerleri giriniz. Yeşil hücreler otomatik ters değerlerdir.
B9: E-09 Su kaynakları (Yeraltı, Yüzey, Şebeke) | C9: =IFERROR(1/D8,"") | D9: 1 | E9: 2 | F9: 2 | G9: 5 | H9: 3 | I9: 4
B10: E-10 Toplam sulanan arazi varlığı (da) | C10: =IFERROR(1/E8,"") | D10: =IFERROR(1/E9,"") | E10: 1 | F10: 0.5 | G10: 3 | H10: 1 | I10: 2
B11: E-11 Su tasarrufu teknikleri (Damla/Yağmurlama) | C11: =IFERROR(1/F8,"") | D11: =IFERROR(1/F9,"") | E11: =IFERROR(1/F10,"") | F11: 1 | G11: 4 | H11: 2 | I11: 3
B12: E-12 Atık su bertaraf ve arıtma yöntemleri | C12: =IFERROR(1/G8,"") | D12: =IFERROR(1/G9,"") | E12: =IFERROR(1/G10,"") | F12: =IFERROR(1/G11,"") | G12: 1 | H12: =1/3 | I12: 0.5
B13: E-13 Sulu Tarım oranı | C13: =IFERROR(1/H8,"") | D13: =IFERROR(1/H9,"") | E13: =IFERROR(1/H10,"") | F13: =IFERROR(1/H11,"") | G13: =IFERROR(1/H12,"") | H13: 1 | I13: 2
B14: E-14 Yıllık Yağış | C14: =IFERROR(1/I8,"") | D14: =IFERROR(1/I9,"") | E14: =IFERROR(1/I10,"") | F14: =IFERROR(1/I11,"") | G14: =IFERROR(1/I12,"") | H14: =IFERROR(1/I13,"") | I14: 1
B17: 2. Normalize matris ve yerel ağırlıklar
C18: E-08 Toplam yıllık su çekimi/tüketimi | D18: E-09 Su kaynakları (Yeraltı, Yüzey, Şebeke) | E18: E-10 Toplam sulanan arazi varlığı (da) | F18: E-11 Su tasarrufu teknikleri (Damla/Yağmurlama) | G18: E-12 Atık su bertaraf ve arıtma yöntemleri | H18: E-13 Sulu Tarım oranı | I18: E-14 Yıllık Yağış | J18: Yerel ağırlık
B19: E-08 Toplam yıllık su çekimi/tüketimi | C19: =IFERROR(C8/C$26,"") | D19: =IFERROR(D8/D$26,"") | E19: =IFERROR(E8/E$26,"") | F19: =IFERROR(F8/F$26,"") | G19: =IFERROR(G8/G$26,"") | H19: =IFERROR(H8/H$26,"") | I19: =IFERROR(I8/I$26,"") | J19: =IFERROR(AVERAGE(C19:I19),"")
B20: E-09 Su kaynakları (Yeraltı, Yüzey, Şebeke) | C20: =IFERROR(C9/C$26,"") | D20: =IFERROR(D9/D$26,"") | E20: =IFERROR(E9/E$26,"") | F20: =IFERROR(F9/F$26,"") | G20: =IFERROR(G9/G$26,"") | H20: =IFERROR(H9/H$26,"") | I20: =IFERROR(I9/I$26,"") | J20: =IFERROR(AVERAGE(C20:I20),"")
B21: E-10 Toplam sulanan arazi varlığı (da) | C21: =IFERROR(C10/C$26,"") | D21: =IFERROR(D10/D$26,"") | E21: =IFERROR(E10/E$26,"") | F21: =IFERROR(F10/F$26,"") | G21: =IFERROR(G10/G$26,"") | H21: =IFERROR(H10/H$26,"") | I21: =IFERROR(I10/I$26,"") | J21: =IFERROR(AVERAGE(C21:I21),"")
B22: E-11 Su tasarrufu teknikleri (Damla/Yağmurlama) | C22: =IFERROR(C11/C$26,"") | D22: =IFERROR(D11/D$26,"") | E22: =IFERROR(E11/E$26,"") | F22: =IFERROR(F11/F$26,"") | G22: =IFERROR(G11/G$26,"") | H22: =IFERROR(H11/H$26,"") | I22: =IFERROR(I11/I$26,"") | J22: =IFERROR(AVERAGE(C22:I22),"")
B23: E-12 Atık su bertaraf ve arıtma yöntemleri | C23: =IFERROR(C12/C$26,"") | D23: =IFERROR(D12/D$26,"") | E23: =IFERROR(E12/E$26,"") | F23: =IFERROR(F12/F$26,"") | G23: =IFERROR(G12/G$26,"") | H23: =IFERROR(H12/H$26,"") | I23: =IFERROR(I12/I$26,"") | J23: =IFERROR(AVERAGE(C23:I23),"")
B24: E-13 Sulu Tarım oranı | C24: =IFERROR(C13/C$26,"") | D24: =IFERROR(D13/D$26,"") | E24: =IFERROR(E13/E$26,"") | F24: =IFERROR(F13/F$26,"") | G24: =IFERROR(G13/G$26,"") | H24: =IFERROR(H13/H$26,"") | I24: =IFERROR(I13/I$26,"") | J24: =IFERROR(AVERAGE(C24:I24),"")
B25: E-14 Yıllık Yağış | C25: =IFERROR(C14/C$26,"") | D25: =IFERROR(D14/D$26,"") | E25: =IFERROR(E14/E$26,"") | F25: =IFERROR(F14/F$26,"") | G25: =IFERROR(G14/G$26,"") | H25: =IFERROR(H14/H$26,"") | I25: =IFERROR(I14/I$26,"") | J25: =IFERROR(AVERAGE(C25:I25),"")
B26: Sütun toplamı | C26: =SUM(C8:C14) | D26: =SUM(D8:D14) | E26: =SUM(E8:E14) | F26: =SUM(F8:F14) | G26: =SUM(G8:G14) | H26: =SUM(H8:H14) | I26: =SUM(I8:I14)
B28: Ağırlık toplamı | J28: =SUM(J19:J25)
B30: 3. Tutarlılık analizi
B31: λmax | J31: =C26*J19+D26*J20+E26*J21+F26*J22+G26*J23+H26*J24+I26*J25
B32: CI | J32: =IFERROR((J31-7)/(7-1),"")
B33: RI (n=7) | J33: 1.32
B34: CR | J34: =IFERROR(J32/J33,"")
B35: Karar | J35: =IF(COUNT(D8,E8,F8,G8,H8,I8,E9,F9,G9,H9,I9,F10,G10,H10,I10,G11,H11,I11,H12,I12,I13)<21,"Veri bekleniyor",IF(J34<=0.1,"Tutarlı (CR ≤ 0,10)","Gözden geçirilmeli (CR > 0,10)"))

Sheet E_BiyoToprak
B2: Çevre → Biyoçeşitlilik ve Toprak Göstergeleri AHP
B4: Karşılaştırma düzeyi | C4: Çevre → Biyoçeşitlilik ve Toprak
B6: 1. İkili karşılaştırma matrisi – sarı hücrelere giriş yapınız
C7: E-15 Korunan alanlara veya hassas ekosistemlere yakınlık | D7: E-16 Biyoçeşitliliği destekleme projeleri | E7: E-17 Toprak analizi | F7: E-18 Münavebe | G7: E-19 Erozyonla mücadele | I7: Giriş açıklaması
B8: E-15 Korunan alanlara veya hassas ekosistemlere yakınlık | C8: 1 | D8: 0.5 | E8: 6 | F8: 3 | G8: 4 | I8: Sarı hücrelere Saaty ölçeğinde 1–9 veya ters değerleri giriniz. Yeşil hücreler otomatik ters değerlerdir.
B9: E-16 Biyoçeşitliliği destekleme projeleri | C9: =IFERROR(1/D8,"") | D9: 1 | E9: 7 | F9: 4 | G9: 5
B10: E-17 Toprak analizi | C10: =IFERROR(1/E8,"") | D10: =IFERROR(1/E9,"") | E10: 1 | F10: 0.5 | G10: 0.25
B11: E-18 Münavebe | C11: =IFERROR(1/F8,"") | D11: =IFERROR(1/F9,"") | E11: =IFERROR(1/F10,"") | F11: 1 | G11: 0.5
B12: E-19 Erozyonla mücadele | C12: =IFERROR(1/G8,"") | D12: =IFERROR(1/G9,"") | E12: =IFERROR(1/G10,"") | F12: =IFERROR(1/G11,"") | G12: 1
B15: 2. Normalize matris ve yerel ağırlıklar
C16: E-15 Korunan alanlara veya hassas ekosistemlere yakınlık | D16: E-16 Biyoçeşitliliği destekleme projeleri | E16: E-17 Toprak analizi | F16: E-18 Münavebe | G16: E-19 Erozyonla mücadele | H16: Yerel ağırlık
B17: E-15 Korunan alanlara veya hassas ekosistemlere yakınlık | C17: =IFERROR(C8/C$22,"") | D17: =IFERROR(D8/D$22,"") | E17: =IFERROR(E8/E$22,"") | F17: =IFERROR(F8/F$22,"") | G17: =IFERROR(G8/G$22,"") | H17: =IFERROR(AVERAGE(C17:G17),"")
B18: E-16 Biyoçeşitliliği destekleme projeleri | C18: =IFERROR(C9/C$22,"") | D18: =IFERROR(D9/D$22,"") | E18: =IFERROR(E9/E$22,"") | F18: =IFERROR(F9/F$22,"") | G18: =IFERROR(G9/G$22,"") | H18: =IFERROR(AVERAGE(C18:G18),"")
B19: E-17 Toprak analizi | C19: =IFERROR(C10/C$22,"") | D19: =IFERROR(D10/D$22,"") | E19: =IFERROR(E10/E$22,"") | F19: =IFERROR(F10/F$22,"") | G19: =IFERROR(G10/G$22,"") | H19: =IFERROR(AVERAGE(C19:G19),"")
B20: E-18 Münavebe | C20: =IFERROR(C11/C$22,"") | D20: =IFERROR(D11/D$22,"") | E20: =IFERROR(E11/E$22,"") | F20: =IFERROR(F11/F$22,"") | G20: =IFERROR(G11/G$22,"") | H20: =IFERROR(AVERAGE(C20:G20),"")
B21: E-19 Erozyonla mücadele | C21: =IFERROR(C12/C$22,"") | D21: =IFERROR(D12/D$22,"") | E21: =IFERROR(E12/E$22,"") | F21: =IFERROR(F12/F$22,"") | G21: =IFERROR(G12/G$22,"") | H21: =IFERROR(AVERAGE(C21:G21),"")
B22: Sütun toplamı | C22: =SUM(C8:C12) | D22: =SUM(D8:D12) | E22: =SUM(E8:E12) | F22: =SUM(F8:F12) | G22: =SUM(G8:G12)
B24: Ağırlık toplamı | H24: =SUM(H17:H21)
B26: 3. Tutarlılık analizi
B27: λmax | H27: =C22*H17+D22*H18+E22*H19+F22*H20+G22*H21
B28: CI | H28: =IFERROR((H27-5)/(5-1),"")
B29: RI (n=5) | H29: 1.12
B30: CR | H30: =IFERROR(H28/H29,"")
B31: Karar | H31: =IF(COUNT(D8,E8,F8,G8,E9,F9,G9,F10,G10,G11)<10,"Veri bekleniyor",IF(H30<=0.1,"Tutarlı (CR ≤ 0,10)","Gözden geçirilmeli (CR > 0,10)"))

Sheet E_AtikKimya
B2: Çevre → Atıklar ve Kimyasallar Göstergeleri AHP
B4: Karşılaştırma düzeyi | C4: Çevre → Atıklar ve Kimyasallar
B6: 1. İkili karşılaştırma matrisi – sarı hücrelere giriş yapınız
C7: E-20 Gübre Kullanımı (Organik/İnorganik) | D7: E-21 Hayvansal gübre yönetimi | E7: E-22 Kimyasal İlaç Kullanımı | F7: E-23 Biyolojik mücadele | G7: E-24 Tehlikeli Atık Bertarafı | H7: E-25 Kimyasal Muhafaza Depoları | I7: E-26 Ambalaj | K7: Giriş açıklaması
B8: E-20 Gübre Kullanımı (Organik/İnorganik) | C8: 1 | D8: 4 | E8: 2 | F8: 5 | G8: 6 | H8: 5 | I8: 7 | K8: Sarı hücrelere Saaty ölçeğinde 1–9 veya ters değerleri giriniz. Yeşil hücreler otomatik ters değerlerdir.
B9: E-21 Hayvansal gübre yönetimi | C9: =IFERROR(1/D8,"") | D9: 1 | E9: 0.5 | F9: 3 | G9: 4 | H9: 3 | I9: 5
B10: E-22 Kimyasal İlaç Kullanımı | C10: =IFERROR(1/E8,"") | D10: =IFERROR(1/E9,"") | E10: 1 | F10: 2 | G10: 5 | H10: 4 | I10: 6
B11: E-23 Biyolojik mücadele | C11: =IFERROR(1/F8,"") | D11: =IFERROR(1/F9,"") | E11: =IFERROR(1/F10,"") | F11: 1 | G11: 3 | H11: 2 | I11: 4
B12: E-24 Tehlikeli Atık Bertarafı | C12: =IFERROR(1/G8,"") | D12: =IFERROR(1/G9,"") | E12: =IFERROR(1/G10,"") | F12: =IFERROR(1/G11,"") | G12: 1 | H12: 0.5 | I12: 2
B13: E-25 Kimyasal Muhafaza Depoları | C13: =IFERROR(1/H8,"") | D13: =IFERROR(1/H9,"") | E13: =IFERROR(1/H10,"") | F13: =IFERROR(1/H11,"") | G13: =IFERROR(1/H12,"") | H13: 1 | I13: 3
B14: E-26 Ambalaj | C14: =IFERROR(1/I8,"") | D14: =IFERROR(1/I9,"") | E14: =IFERROR(1/I10,"") | F14: =IFERROR(1/I11,"") | G14: =IFERROR(1/I12,"") | H14: =IFERROR(1/I13,"") | I14: 1
B17: 2. Normalize matris ve yerel ağırlıklar
C18: E-20 Gübre Kullanımı (Organik/İnorganik) | D18: E-21 Hayvansal gübre yönetimi | E18: E-22 Kimyasal İlaç Kullanımı | F18: E-23 Biyolojik mücadele | G18: E-24 Tehlikeli Atık Bertarafı | H18: E-25 Kimyasal Muhafaza Depoları | I18: E-26 Ambalaj | J18: Yerel ağırlık
B19: E-20 Gübre Kullanımı (Organik/İnorganik) | C19: =IFERROR(C8/C$26,"") | D19: =IFERROR(D8/D$26,"") | E19: =IFERROR(E8/E$26,"") | F19: =IFERROR(F8/F$26,"") | G19: =IFERROR(G8/G$26,"") | H19: =IFERROR(H8/H$26,"") | I19: =IFERROR(I8/I$26,"") | J19: =IFERROR(AVERAGE(C19:I19),"")
B20: E-21 Hayvansal gübre yönetimi | C20: =IFERROR(C9/C$26,"") | D20: =IFERROR(D9/D$26,"") | E20: =IFERROR(E9/E$26,"") | F20: =IFERROR(F9/F$26,"") | G20: =IFERROR(G9/G$26,"") | H20: =IFERROR(H9/H$26,"") | I20: =IFERROR(I9/I$26,"") | J20: =IFERROR(AVERAGE(C20:I20),"")
B21: E-22 Kimyasal İlaç Kullanımı | C21: =IFERROR(C10/C$26,"") | D21: =IFERROR(D10/D$26,"") | E21: =IFERROR(E10/E$26,"") | F21: =IFERROR(F10/F$26,"") | G21: =IFERROR(G10/G$26,"") | H21: =IFERROR(H10/H$26,"") | I21: =IFERROR(I10/I$26,"") | J21: =IFERROR(AVERAGE(C21:I21),"")
B22: E-23 Biyolojik mücadele | C22: =IFERROR(C11/C$26,"") | D22: =IFERROR(D11/D$26,"") | E22: =IFERROR(E11/E$26,"") | F22: =IFERROR(F11/F$26,"") | G22: =IFERROR(G11/G$26,"") | H22: =IFERROR(H11/H$26,"") | I22: =IFERROR(I11/I$26,"") | J22: =IFERROR(AVERAGE(C22:I22),"")
B23: E-24 Tehlikeli Atık Bertarafı | C23: =IFERROR(C12/C$26,"") | D23: =IFERROR(D12/D$26,"") | E23: =IFERROR(E12/E$26,"") | F23: =IFERROR(F12/F$26,"") | G23: =IFERROR(G12/G$26,"") | H23: =IFERROR(H12/H$26,"") | I23: =IFERROR(I12/I$26,"") | J23: =IFERROR(AVERAGE(C23:I23),"")
B24: E-25 Kimyasal Muhafaza Depoları | C24: =IFERROR(C13/C$26,"") | D24: =IFERROR(D13/D$26,"") | E24: =IFERROR(E13/E$26,"") | F24: =IFERROR(F13/F$26,"") | G24: =IFERROR(G13/G$26,"") | H24: =IFERROR(H13/H$26,"") | I24: =IFERROR(I13/I$26,"") | J24: =IFERROR(AVERAGE(C24:I24),"")
B25: E-26 Ambalaj | C25: =IFERROR(C14/C$26,"") | D25: =IFERROR(D14/D$26,"") | E25: =IFERROR(E14/E$26,"") | F25: =IFERROR(F14/F$26,"") | G25: =IFERROR(G14/G$26,"") | H25: =IFERROR(H14/H$26,"") | I25: =IFERROR(I14/I$26,"") | J25: =IFERROR(AVERAGE(C25:I25),"")
B26: Sütun toplamı | C26: =SUM(C8:C14) | D26: =SUM(D8:D14) | E26: =SUM(E8:E14) | F26: =SUM(F8:F14) | G26: =SUM(G8:G14) | H26: =SUM(H8:H14) | I26: =SUM(I8:I14)
B28: Ağırlık toplamı | J28: =SUM(J19:J25)
B30: 3. Tutarlılık analizi
B31: λmax | J31: =C26*J19+D26*J20+E26*J21+F26*J22+G26*J23+H26*J24+I26*J25
B32: CI | J32: =IFERROR((J31-7)/(7-1),"")
B33: RI (n=7) | J33: 1.32
B34: CR | J34: =IFERROR(J32/J33,"")
B35: Karar | J35: =IF(COUNT(D8,E8,F8,G8,H8,I8,E9,F9,G9,H9,I9,F10,G10,H10,I10,G11,H11,I11,H12,I12,I13)<21,"Veri bekleniyor",IF(J34<=0.1,"Tutarlı (CR ≤ 0,10)","Gözden geçirilmeli (CR > 0,10)"))

Sheet S_AltGruplar
B2: Sosyal Ana Bloğu Alt Grupları AHP
B4: Karşılaştırma düzeyi | C4: Sosyal ana bloğu alt grup karşılaştırması
B6: 1. İkili karşılaştırma matrisi – sarı hücrelere giriş yapınız
C7: İşgücü / İstihdam | D7: Çalışma Koşulları | E7: Toplum/Kişisel Koruma | G7: Giriş açıklaması
B8: İşgücü / İstihdam | C8: 1 | D8: 2 | E8: 0.5 | G8: Sarı hücrelere Saaty ölçeğinde 1–9 veya ters değerleri giriniz. Yeşil hücreler otomatik ters değerlerdir.
B9: Çalışma Koşulları | C9: =IFERROR(1/D8,"") | D9: 1 | E9: =1/3
B10: Toplum/Kişisel Koruma | C10: =IFERROR(1/E8,"") | D10: =IFERROR(1/E9,"") | E10: 1
B13: 2. Normalize matris ve yerel ağırlıklar
C14: İşgücü / İstihdam | D14: Çalışma Koşulları | E14: Toplum/Kişisel Koruma | F14: Yerel ağırlık
B15: İşgücü / İstihdam | C15: =IFERROR(C8/C$18,"") | D15: =IFERROR(D8/D$18,"") | E15: =IFERROR(E8/E$18,"") | F15: =IFERROR(AVERAGE(C15:E15),"")
B16: Çalışma Koşulları | C16: =IFERROR(C9/C$18,"") | D16: =IFERROR(D9/D$18,"") | E16: =IFERROR(E9/E$18,"") | F16: =IFERROR(AVERAGE(C16:E16),"")
B17: Toplum/Kişisel Koruma | C17: =IFERROR(C10/C$18,"") | D17: =IFERROR(D10/D$18,"") | E17: =IFERROR(E10/E$18,"") | F17: =IFERROR(AVERAGE(C17:E17),"")
B18: Sütun toplamı | C18: =SUM(C8:C10) | D18: =SUM(D8:D10) | E18: =SUM(E8:E10)
B20: Ağırlık toplamı | F20: =SUM(F15:F17)
B22: 3. Tutarlılık analizi
B23: λmax | F23: =C18*F15+D18*F16+E18*F17
B24: CI | F24: =IFERROR((F23-3)/(3-1),"")
B25: RI (n=3) | F25: 0.58
B26: CR | F26: =IFERROR(F24/F25,"")
B27: Karar | F27: =IF(COUNT(D8,E8,E9)<3,"Veri bekleniyor",IF(F26<=0.1,"Tutarlı (CR ≤ 0,10)","Gözden geçirilmeli (CR > 0,10)"))

Sheet S_IsgucuIst
B2: Sosyal → İşgücü / İstihdam Göstergeleri AHP
B4: Karşılaştırma düzeyi | C4: Sosyal → İşgücü / İstihdam
B6: 1. İkili karşılaştırma matrisi – sarı hücrelere giriş yapınız
C7: S-27 Kadro Dağılımları | D7: S-28 Taşeron oranı | E7: S-29 Yaş Dağılımı | F7: S-30 Sendikalılık | G7: S-31 Çalışma Süreleri | H7: S-32 Eğitim | I7: S-33 Cinsiyet | J7: S-34 Devir Daim Hızı | K7: S-35 Eski Hükümlü/Engelli personel | M7: Giriş açıklaması
B8: S-27 Kadro Dağılımları | C8: 1 | D8: 2 | E8: 3 | F8: 6 | G8: 4 | H8: 4 | I8: 5 | J8: 6 | K8: 8 | M8: Sarı hücrelere Saaty ölçeğinde 1–9 veya ters değerleri giriniz. Yeşil hücreler otomatik ters değerlerdir.
B9: S-28 Taşeron oranı | C9: =IFERROR(1/D8,"") | D9: 1 | E9: 2 | F9: 5 | G9: 3 | H9: 3 | I9: 4 | J9: 5 | K9: 7
B10: S-29 Yaş Dağılımı | C10: =IFERROR(1/E8,"") | D10: =IFERROR(1/E9,"") | E10: 1 | F10: 4 | G10: 2 | H10: 0.5 | I10: 2 | J10: 4 | K10: 6
B11: S-30 Sendikalılık | C11: =IFERROR(1/F8,"") | D11: =IFERROR(1/F9,"") | E11: =IFERROR(1/F10,"") | F11: 1 | G11: =1/3 | H11: 0.25 | I11: 0.2 | J11: 0.2 | K11: 2
B12: S-31 Çalışma Süreleri | C12: =IFERROR(1/G8,"") | D12: =IFERROR(1/G9,"") | E12: =IFERROR(1/G10,"") | F12: =IFERROR(1/G11,"") | G12: 1 | H12: =1/3 | I12: 0.5 | J12: 0.5 | K12: 5
B13: S-32 Eğitim | C13: =IFERROR(1/H8,"") | D13: =IFERROR(1/H9,"") | E13: =IFERROR(1/H10,"") | F13: =IFERROR(1/H11,"") | G13: =IFERROR(1/H12,"") | H13: 1 | I13: 3 | J13: 4 | K13: 6
B14: S-33 Cinsiyet | C14: =IFERROR(1/I8,"") | D14: =IFERROR(1/I9,"") | E14: =IFERROR(1/I10,"") | F14: =IFERROR(1/I11,"") | G14: =IFERROR(1/I12,"") | H14: =IFERROR(1/I13,"") | I14: 1 | J14: 2 | K14: 5
B15: S-34 Devir Daim Hızı | C15: =IFERROR(1/J8,"") | D15: =IFERROR(1/J9,"") | E15: =IFERROR(1/J10,"") | F15: =IFERROR(1/J11,"") | G15: =IFERROR(1/J12,"") | H15: =IFERROR(1/J13,"") | I15: =IFERROR(1/J14,"") | J15: 1 | K15: 3
B16: S-35 Eski Hükümlü/Engelli personel | C16: =IFERROR(1/K8,"") | D16: =IFERROR(1/K9,"") | E16: =IFERROR(1/K10,"") | F16: =IFERROR(1/K11,"") | G16: =IFERROR(1/K12,"") | H16: =IFERROR(1/K13,"") | I16: =IFERROR(1/K14,"") | J16: =IFERROR(1/K15,"") | K16: 1
B19: 2. Normalize matris ve yerel ağırlıklar
C20: S-27 Kadro Dağılımları | D20: S-28 Taşeron oranı | E20: S-29 Yaş Dağılımı | F20: S-30 Sendikalılık | G20: S-31 Çalışma Süreleri | H20: S-32 Eğitim | I20: S-33 Cinsiyet | J20: S-34 Devir Daim Hızı | K20: S-35 Eski Hükümlü/Engelli personel | L20: Yerel ağırlık
B21: S-27 Kadro Dağılımları | C21: =IFERROR(C8/C$30,"") | D21: =IFERROR(D8/D$30,"") | E21: =IFERROR(E8/E$30,"") | F21: =IFERROR(F8/F$30,"") | G21: =IFERROR(G8/G$30,"") | H21: =IFERROR(H8/H$30,"") | I21: =IFERROR(I8/I$30,"") | J21: =IFERROR(J8/J$30,"") | K21: =IFERROR(K8/K$30,"") | L21: =IFERROR(AVERAGE(C21:K21),"")
B22: S-28 Taşeron oranı | C22: =IFERROR(C9/C$30,"") | D22: =IFERROR(D9/D$30,"") | E22: =IFERROR(E9/E$30,"") | F22: =IFERROR(F9/F$30,"") | G22: =IFERROR(G9/G$30,"") | H22: =IFERROR(H9/H$30,"") | I22: =IFERROR(I9/I$30,"") | J22: =IFERROR(J9/J$30,"") | K22: =IFERROR(K9/K$30,"") | L22: =IFERROR(AVERAGE(C22:K22),"")
B23: S-29 Yaş Dağılımı | C23: =IFERROR(C10/C$30,"") | D23: =IFERROR(D10/D$30,"") | E23: =IFERROR(E10/E$30,"") | F23: =IFERROR(F10/F$30,"") | G23: =IFERROR(G10/G$30,"") | H23: =IFERROR(H10/H$30,"") | I23: =IFERROR(I10/I$30,"") | J23: =IFERROR(J10/J$30,"") | K23: =IFERROR(K10/K$30,"") | L23: =IFERROR(AVERAGE(C23:K23),"")
B24: S-30 Sendikalılık | C24: =IFERROR(C11/C$30,"") | D24: =IFERROR(D11/D$30,"") | E24: =IFERROR(E11/E$30,"") | F24: =IFERROR(F11/F$30,"") | G24: =IFERROR(G11/G$30,"") | H24: =IFERROR(H11/H$30,"") | I24: =IFERROR(I11/I$30,"") | J24: =IFERROR(J11/J$30,"") | K24: =IFERROR(K11/K$30,"") | L24: =IFERROR(AVERAGE(C24:K24),"")
B25: S-31 Çalışma Süreleri | C25: =IFERROR(C12/C$30,"") | D25: =IFERROR(D12/D$30,"") | E25: =IFERROR(E12/E$30,"") | F25: =IFERROR(F12/F$30,"") | G25: =IFERROR(G12/G$30,"") | H25: =IFERROR(H12/H$30,"") | I25: =IFERROR(I12/I$30,"") | J25: =IFERROR(J12/J$30,"") | K25: =IFERROR(K12/K$30,"") | L25: =IFERROR(AVERAGE(C25:K25),"")
B26: S-32 Eğitim | C26: =IFERROR(C13/C$30,"") | D26: =IFERROR(D13/D$30,"") | E26: =IFERROR(E13/E$30,"") | F26: =IFERROR(F13/F$30,"") | G26: =IFERROR(G13/G$30,"") | H26: =IFERROR(H13/H$30,"") | I26: =IFERROR(I13/I$30,"") | J26: =IFERROR(J13/J$30,"") | K26: =IFERROR(K13/K$30,"") | L26: =IFERROR(AVERAGE(C26:K26),"")
B27: S-33 Cinsiyet | C27: =IFERROR(C14/C$30,"") | D27: =IFERROR(D14/D$30,"") | E27: =IFERROR(E14/E$30,"") | F27: =IFERROR(F14/F$30,"") | G27: =IFERROR(G14/G$30,"") | H27: =IFERROR(H14/H$30,"") | I27: =IFERROR(I14/I$30,"") | J27: =IFERROR(J14/J$30,"") | K27: =IFERROR(K14/K$30,"") | L27: =IFERROR(AVERAGE(C27:K27),"")
B28: S-34 Devir Daim Hızı | C28: =IFERROR(C15/C$30,"") | D28: =IFERROR(D15/D$30,"") | E28: =IFERROR(E15/E$30,"") | F28: =IFERROR(F15/F$30,"") | G28: =IFERROR(G15/G$30,"") | H28: =IFERROR(H15/H$30,"") | I28: =IFERROR(I15/I$30,"") | J28: =IFERROR(J15/J$30,"") | K28: =IFERROR(K15/K$30,"") | L28: =IFERROR(AVERAGE(C28:K28),"")
B29: S-35 Eski Hükümlü/Engelli personel | C29: =IFERROR(C16/C$30,"") | D29: =IFERROR(D16/D$30,"") | E29: =IFERROR(E16/E$30,"") | F29: =IFERROR(F16/F$30,"") | G29: =IFERROR(G16/G$30,"") | H29: =IFERROR(H16/H$30,"") | I29: =IFERROR(I16/I$30,"") | J29: =IFERROR(J16/J$30,"") | K29: =IFERROR(K16/K$30,"") | L29: =IFERROR(AVERAGE(C29:K29),"")
B30: Sütun toplamı | C30: =SUM(C8:C16) | D30: =SUM(D8:D16) | E30: =SUM(E8:E16) | F30: =SUM(F8:F16) | G30: =SUM(G8:G16) | H30: =SUM(H8:H16) | I30: =SUM(I8:I16) | J30: =SUM(J8:J16) | K30: =SUM(K8:K16)
B32: Ağırlık toplamı | L32: =SUM(L21:L29)
B34: 3. Tutarlılık analizi
B35: λmax | L35: =C30*L21+D30*L22+E30*L23+F30*L24+G30*L25+H30*L26+I30*L27+J30*L28+K30*L29
B36: CI | L36: =IFERROR((L35-9)/(9-1),"")
B37: RI (n=9) | L37: 1.45
B38: CR | L38: =IFERROR(L36/L37,"")
B39: Karar | L39: =IF(COUNT(D8,E8,F8,G8,H8,I8,J8,K8,E9,F9,G9,H9,I9,J9,K9,F10,G10,H10,I10,J10,K10,G11,H11,I11,J11,K11,H12,I12,J12,K12,I13,J13,K13,J14,K14,K15)<36,"Veri bekleniyor",IF(L38<=0.1,"Tutarlı (CR ≤ 0,10)","Gözden geçirilmeli (CR > 0,10)"))

Sheet S_CalismaKos
B2: Sosyal → Çalışma Koşulları Göstergeleri AHP
B4: Karşılaştırma düzeyi | C4: Sosyal → Çalışma Koşulları
B6: 1. İkili karşılaştırma matrisi – sarı hücrelere giriş yapınız
C7: S-36 Ortalama fazla mesai süreleri | D7: S-37 Stajyer sayısı | E7: S-38 Çalışanlar tarafından açılan davalar | F7: S-39 Memnuniyet anketleri/şikayetler | G7: S-40 İş kazaları | H7: S-41 Meslek Hastalıkları | I7: S-42 İSG (Eğitimler/İSG Uzmanı istihdamı) | J7: S-43 Sağlık Hizmetleri | K7: Yerel ağırlık | L7: Giriş açıklaması
B8: S-36 Ortalama fazla mesai süreleri | C8: 1 | D8: 3 | E8: =1/3 | F8: 2 | G8: =1/3 | H8: 0.5 | I8: 0.25 | J8: 0.5 | L8: Sarı hücrelere Saaty ölçeğinde 1–9 veya ters değerleri giriniz. Yeşil hücreler otomatik ters değerlerdir.
B9: S-37 Stajyer sayısı | C9: =IFERROR(1/D8,"") | D9: 1 | E9: 0.25 | F9: 0.5 | G9: 0.2 | H9: 0.2 | I9: 0.2 | J9: 0.2
B10: S-38 Çalışanlar tarafından açılan davalar | C10: =IFERROR(1/E8,"") | D10: =IFERROR(1/E9,"") | E10: 1 | F10: 4 | G10: 0.5 | H10: 2 | I10: 3 | J10: 5
B11: S-39 Memnuniyet anketleri/şikayetler | C11: =IFERROR(1/F8,"") | D11: =IFERROR(1/F9,"") | E11: =IFERROR(1/F10,"") | F11: 1 | G11: 0.2 | H11: 0.25 | I11: 0.2 | J11: 0.5
B12: S-40 İş kazaları | C12: =IFERROR(1/G8,"") | D12: =IFERROR(1/G9,"") | E12: =IFERROR(1/G10,"") | F12: =IFERROR(1/G11,"") | G12: 1 | H12: 3 | I12: 4 | J12: 5
B13: S-41 Meslek Hastalıkları | C13: =IFERROR(1/H8,"") | D13: =IFERROR(1/H9,"") | E13: =IFERROR(1/H10,"") | F13: =IFERROR(1/H11,"") | G13: =IFERROR(1/H12,"") | H13: 1 | I13: 0.5 | J13: 2
B14: S-42 İSG (Eğitimler/İSG Uzmanı istihdamı) | C14: =IFERROR(1/I8,"") | D14: =IFERROR(1/I9,"") | E14: =IFERROR(1/I10,"") | F14: =IFERROR(1/I11,"") | G14: =IFERROR(1/I12,"") | H14: =IFERROR(1/I13,"") | I14: 1 | J14: 3
B15: S-43 Sağlık Hizmetleri | C15: =IFERROR(1/J8,"") | D15: =IFERROR(1/J9,"") | E15: =IFERROR(1/J10,"") | F15: =IFERROR(1/J11,"") | G15: =IFERROR(1/J12,"") | H15: =IFERROR(1/J13,"") | I15: =IFERROR(1/J14,"") | J15: 1
B18: 2. Normalize matris ve yerel ağırlıklar
C19: S-36 Ortalama fazla mesai süreleri | D19: S-37 Stajyer sayısı | E19: S-38 Çalışanlar tarafından açılan davalar | F19: S-39 Memnuniyet anketleri/şikayetler | G19: S-40 İş kazaları | H19: S-41 Meslek Hastalıkları | I19: S-42 İSG (Eğitimler/İSG Uzmanı istihdamı) | J19: S-43 Sağlık Hizmetleri | K19: Yerel ağırlık
B20: S-36 Ortalama fazla mesai süreleri | C20: =IFERROR(C8/C$28,"") | D20: =IFERROR(D8/D$28,"") | E20: =IFERROR(E8/E$28,"") | F20: =IFERROR(F8/F$28,"") | G20: =IFERROR(G8/G$28,"") | H20: =IFERROR(H8/H$28,"") | I20: =IFERROR(I8/I$28,"") | J20: =IFERROR(J8/J$28,"") | K20: =IFERROR(AVERAGE(C20:J20),"")
B21: S-37 Stajyer sayısı | C21: =IFERROR(C9/C$28,"") | D21: =IFERROR(D9/D$28,"") | E21: =IFERROR(E9/E$28,"") | F21: =IFERROR(F9/F$28,"") | G21: =IFERROR(G9/G$28,"") | H21: =IFERROR(H9/H$28,"") | I21: =IFERROR(I9/I$28,"") | J21: =IFERROR(J9/J$28,"") | K21: =IFERROR(AVERAGE(C21:J21),"")
B22: S-38 Çalışanlar tarafından açılan davalar | C22: =IFERROR(C10/C$28,"") | D22: =IFERROR(D10/D$28,"") | E22: =IFERROR(E10/E$28,"") | F22: =IFERROR(F10/F$28,"") | G22: =IFERROR(G10/G$28,"") | H22: =IFERROR(H10/H$28,"") | I22: =IFERROR(I10/I$28,"") | J22: =IFERROR(J10/J$28,"") | K22: =IFERROR(AVERAGE(C22:J22),"")
B23: S-39 Memnuniyet anketleri/şikayetler | C23: =IFERROR(C11/C$28,"") | D23: =IFERROR(D11/D$28,"") | E23: =IFERROR(E11/E$28,"") | F23: =IFERROR(F11/F$28,"") | G23: =IFERROR(G11/G$28,"") | H23: =IFERROR(H11/H$28,"") | I23: =IFERROR(I11/I$28,"") | J23: =IFERROR(J11/J$28,"") | K23: =IFERROR(AVERAGE(C23:J23),"")
B24: S-40 İş kazaları | C24: =IFERROR(C12/C$28,"") | D24: =IFERROR(D12/D$28,"") | E24: =IFERROR(E12/E$28,"") | F24: =IFERROR(F12/F$28,"") | G24: =IFERROR(G12/G$28,"") | H24: =IFERROR(H12/H$28,"") | I24: =IFERROR(I12/I$28,"") | J24: =IFERROR(J12/J$28,"") | K24: =IFERROR(AVERAGE(C24:J24),"")
B25: S-41 Meslek Hastalıkları | C25: =IFERROR(C13/C$28,"") | D25: =IFERROR(D13/D$28,"") | E25: =IFERROR(E13/E$28,"") | F25: =IFERROR(F13/F$28,"") | G25: =IFERROR(G13/G$28,"") | H25: =IFERROR(H13/H$28,"") | I25: =IFERROR(I13/I$28,"") | J25: =IFERROR(J13/J$28,"") | K25: =IFERROR(AVERAGE(C25:J25),"")
B26: S-42 İSG (Eğitimler/İSG Uzmanı istihdamı) | C26: =IFERROR(C14/C$28,"") | D26: =IFERROR(D14/D$28,"") | E26: =IFERROR(E14/E$28,"") | F26: =IFERROR(F14/F$28,"") | G26: =IFERROR(G14/G$28,"") | H26: =IFERROR(H14/H$28,"") | I26: =IFERROR(I14/I$28,"") | J26: =IFERROR(J14/J$28,"") | K26: =IFERROR(AVERAGE(C26:J26),"")
B27: S-43 Sağlık Hizmetleri | C27: =IFERROR(C15/C$28,"") | D27: =IFERROR(D15/D$28,"") | E27: =IFERROR(E15/E$28,"") | F27: =IFERROR(F15/F$28,"") | G27: =IFERROR(G15/G$28,"") | H27: =IFERROR(H15/H$28,"") | I27: =IFERROR(I15/I$28,"") | J27: =IFERROR(J15/J$28,"") | K27: =IFERROR(AVERAGE(C27:J27),"")
B28: Sütun toplamı | C28: =SUM(C8:C15) | D28: =SUM(D8:D15) | E28: =SUM(E8:E15) | F28: =SUM(F8:F15) | G28: =SUM(G8:G15) | H28: =SUM(H8:H15) | I28: =SUM(I8:I15) | J28: =SUM(J8:J15)
B30: Ağırlık toplamı | K30: =SUM(K20:K27)
B32: 3. Tutarlılık analizi
B33: λmax | K33: =C28*K20+D28*K21+E28*K22+F28*K23+G28*K24+H28*K25+I28*K26+J28*K27
B34: CI | K34: =IFERROR((K33-8)/(8-1),"")
B35: RI (n=8) | K35: 1.41
B36: CR | K36: =IFERROR(K34/K35,"")
B37: Karar | K37: =IF(COUNT(D8,E8,F8,G8,H8,I8,J8,E9,F9,G9,H9,I9,J9,F10,G10,H10,I10,J10,G11,H11,I11,J11,H12,I12,J12,I13,J13,J14)<28,"Veri bekleniyor",IF(K36<=0.1,"Tutarlı (CR ≤ 0,10)","Gözden geçirilmeli (CR > 0,10)"))

Sheet S_ToplumKor
B2: Sosyal → Toplum / Kişisel Koruma Göstergeleri AHP
B4: Karşılaştırma düzeyi | C4: Sosyal → Toplum / Kişisel Koruma
B6: 1. İkili karşılaştırma matrisi – sarı hücrelere giriş yapınız
C7: S-44 KKD | D7: S-45 Yerel Topluluklara fayda | E7: S-46 Mesleki eğitimler | G7: Giriş açıklaması
B8: S-44 KKD | C8: 1 | D8: 3 | E8: 5 | G8: Sarı hücrelere Saaty ölçeğinde 1–9 veya ters değerleri giriniz. Yeşil hücreler otomatik ters değerlerdir.
B9: S-45 Yerel Topluluklara fayda | C9: =IFERROR(1/D8,"") | D9: 1 | E9: 2
B10: S-46 Mesleki eğitimler | C10: =IFERROR(1/E8,"") | D10: =IFERROR(1/E9,"") | E10: 1
B13: 2. Normalize matris ve yerel ağırlıklar
C14: S-44 KKD | D14: S-45 Yerel Topluluklara fayda | E14: S-46 Mesleki eğitimler | F14: Yerel ağırlık
B15: S-44 KKD | C15: =IFERROR(C8/C$18,"") | D15: =IFERROR(D8/D$18,"") | E15: =IFERROR(E8/E$18,"") | F15: =IFERROR(AVERAGE(C15:E15),"")
B16: S-45 Yerel Topluluklara fayda | C16: =IFERROR(C9/C$18,"") | D16: =IFERROR(D9/D$18,"") | E16: =IFERROR(E9/E$18,"") | F16: =IFERROR(AVERAGE(C16:E16),"")
B17: S-46 Mesleki eğitimler | C17: =IFERROR(C10/C$18,"") | D17: =IFERROR(D10/D$18,"") | E17: =IFERROR(E10/E$18,"") | F17: =IFERROR(AVERAGE(C17:E17),"")
B18: Sütun toplamı | C18: =SUM(C8:C10) | D18: =SUM(D8:D10) | E18: =SUM(E8:E10)
B20: Ağırlık toplamı | F20: =SUM(F15:F17)
B22: 3. Tutarlılık analizi
B23: λmax | F23: =C18*F15+D18*F16+E18*F17
B24: CI | F24: =IFERROR((F23-3)/(3-1),"")
B25: RI (n=3) | F25: 0.58
B26: CR | F26: =IFERROR(F24/F25,"")
B27: Karar | F27: =IF(COUNT(D8,E8,E9)<3,"Veri bekleniyor",IF(F26<=0.1,"Tutarlı (CR ≤ 0,10)","Gözden geçirilmeli (CR > 0,10)"))

Sheet G_AltGruplar
B2: Yönetişim Ana Bloğu Alt Grupları AHP
B4: Karşılaştırma düzeyi | C4: Yönetişim ana bloğu alt grup karşılaştırması
B6: 1. İkili karşılaştırma matrisi – sarı hücrelere giriş yapınız
C7: Uyum ve Politika | D7: Tedarik Zinciri ve Risk | F7: Giriş açıklaması
B8: Uyum ve Politika | C8: 1 | D8: 2 | F8: Sarı hücrelere Saaty ölçeğinde 1–9 veya ters değerleri giriniz. Yeşil hücreler otomatik ters değerlerdir.
B9: Tedarik Zinciri ve Risk | C9: =IFERROR(1/D8,"") | D9: 1
B12: 2. Normalize matris ve yerel ağırlıklar
C13: Uyum ve Politika | D13: Tedarik Zinciri ve Risk | E13: Yerel ağırlık
B14: Uyum ve Politika | C14: =IFERROR(C8/C$16,"") | D14: =IFERROR(D8/D$16,"") | E14: =IFERROR(AVERAGE(C14:D14),"")
B15: Tedarik Zinciri ve Risk | C15: =IFERROR(C9/C$16,"") | D15: =IFERROR(D9/D$16,"") | E15: =IFERROR(AVERAGE(C15:D15),"")
B16: Sütun toplamı | C16: =SUM(C8:C9) | D16: =SUM(D8:D9)
B18: Ağırlık toplamı | E18: =SUM(E14:E15)
B20: 3. Tutarlılık analizi
B21: λmax | E21: =C16*E14+D16*E15
B22: CI | E22: =IFERROR((E21-2)/(2-1),"")
B23: RI (n=2) | E23: 0
B24: CR | E24: Uygulanamaz
B25: Karar | E25: 2'li matris -Doğrudan kontrol

Sheet G_UyumPolit
B2: Yönetişim → Uyum ve Politika Göstergeleri AHP
B4: Karşılaştırma düzeyi | C4: Yönetişim → Uyum ve Politika
B6: 1. İkili karşılaştırma matrisi – sarı hücrelere giriş yapınız
C7: G-47 İşletme Genel Bilgileri (kuruluş tarihçesi, coğrafi konum, büyüklük, ürün çeşidi) | D7: G-48 Ürün çeşitliliği | E7: G-49 Etik | F7: G-50 Çevre ve İklim Değişikliği Strateji Belgesi | G7: G-51 Çevre Mevzuatına Uyum | H7: G-52 İş Hukuku ve Sosyal Haklara Uyum | I7: G-53 İç Kontrol Sisteminin Etkinliği | J7: G-54 Stratejik Hedeflerde sürdürülebilirlik kriterleri | K7: G-55 Şeffaflık (Raporlama) | L7: G-56 Denetlenebilirlik | M7: G-57 İç Denetimin Bağımsızlık Düzeyi | N7: G-58 Sürdürülebilirlik Denetimi geçmişi | P7: Giriş açıklaması
B8: G-47 İşletme Genel Bilgileri (kuruluş tarihçesi, coğrafi konum, büyüklük, ürün çeşidi) | C8: 1 | D8: 6 | E8: 5 | F8: 3 | G8: 0.5 | H8: =1/3 | I8: 0.5 | J8: 2 | K8: 0.5 | L8: 0.5 | M8: 1 | N8: 2 | P8: Sarı hücrelere Saaty ölçeğinde 1–9 veya ters değerleri giriniz. Yeşil hücreler otomatik ters değerlerdir.
B9: G-48 Ürün çeşitliliği | C9: =IFERROR(1/D8,"") | D9: 1 | E9: 2 | F9: 0.2 | G9: 0.2 | H9: 0.2 | I9: 0.2 | J9: =1/3 | K9: 0.2 | L9: 0.2 | M9: 0.25 | N9: 0.2
B10: G-49 Etik | C10: =IFERROR(1/E8,"") | D10: =IFERROR(1/E9,"") | E10: 1 | F10: 0.5 | G10: 0.25 | H10: 0.25 | I10: 0.25 | J10: 0.5 | K10: 0.25 | L10: 0.25 | M10: =1/3 | N10: 0.25
B11: G-50 Çevre ve İklim Değişikliği Strateji Belgesi | C11: =IFERROR(1/F8,"") | D11: =IFERROR(1/F9,"") | E11: =IFERROR(1/F10,"") | F11: 1 | G11: =1/3 | H11: 0.25 | I11: 0.5 | J11: 3 | K11: =1/3 | L11: 0.25 | M11: 0.5 | N11: 0.5
B12: G-51 Çevre Mevzuatına Uyum | C12: =IFERROR(1/G8,"") | D12: =IFERROR(1/G9,"") | E12: =IFERROR(1/G10,"") | F12: =IFERROR(1/G11,"") | G12: 1 | H12: 1 | I12: 3 | J12: 5 | K12: 3 | L12: 1 | M12: 3 | N12: 4
B13: G-52 İş Hukuku ve Sosyal Haklara Uyum | C13: =IFERROR(1/H8,"") | D13: =IFERROR(1/H9,"") | E13: =IFERROR(1/H10,"") | F13: =IFERROR(1/H11,"") | G13: =IFERROR(1/H12,"") | H13: 1 | I13: 3 | J13: 6 | K13: 3 | L13: 1 | M13: 3 | N13: 4
B14: G-53 İç Kontrol Sisteminin Etkinliği | C14: =IFERROR(1/I8,"") | D14: =IFERROR(1/I9,"") | E14: =IFERROR(1/I10,"") | F14: =IFERROR(1/I11,"") | G14: =IFERROR(1/I12,"") | H14: =IFERROR(1/I13,"") | I14: 1 | J14: 4 | K14: 0.5 | L14: 0.5 | M14: 2 | N14: 2
B15: G-54 Stratejik Hedeflerde sürdürülebilirlik kriterleri | C15: =IFERROR(1/J8,"") | D15: =IFERROR(1/J9,"") | E15: =IFERROR(1/J10,"") | F15: =IFERROR(1/J11,"") | G15: =IFERROR(1/J12,"") | H15: =IFERROR(1/J13,"") | I15: =IFERROR(1/J14,"") | J15: 1 | K15: =1/3 | L15: =1/3 | M15: 0.5 | N15: 0.5
B16: G-55 Şeffaflık (Raporlama) | C16: =IFERROR(1/K8,"") | D16: =IFERROR(1/K9,"") | E16: =IFERROR(1/K10,"") | F16: =IFERROR(1/K11,"") | G16: =IFERROR(1/K12,"") | H16: =IFERROR(1/K13,"") | I16: =IFERROR(1/K14,"") | J16: =IFERROR(1/K15,"") | K16: 1 | L16: 0.5 | M16: 3 | N16: 4
B17: G-56 Denetlenebilirlik | C17: =IFERROR(1/L8,"") | D17: =IFERROR(1/L9,"") | E17: =IFERROR(1/L10,"") | F17: =IFERROR(1/L11,"") | G17: =IFERROR(1/L12,"") | H17: =IFERROR(1/L13,"") | I17: =IFERROR(1/L14,"") | J17: =IFERROR(1/L15,"") | K17: =IFERROR(1/L16,"") | L17: 1 | M17: 4 | N17: 5
B18: G-57 İç Denetimin Bağımsızlık Düzeyi | C18: =IFERROR(1/M8,"") | D18: =IFERROR(1/M9,"") | E18: =IFERROR(1/M10,"") | F18: =IFERROR(1/M11,"") | G18: =IFERROR(1/M12,"") | H18: =IFERROR(1/M13,"") | I18: =IFERROR(1/M14,"") | J18: =IFERROR(1/M15,"") | K18: =IFERROR(1/M16,"") | L18: =IFERROR(1/M17,"") | M18: 1 | N18: 2
B19: G-58 Sürdürülebilirlik Denetimi geçmişi | C19: =IFERROR(1/N8,"") | D19: =IFERROR(1/N9,"") | E19: =IFERROR(1/N10,"") | F19: =IFERROR(1/N11,"") | G19: =IFERROR(1/N12,"") | H19: =IFERROR(1/N13,"") | I19: =IFERROR(1/N14,"") | J19: =IFERROR(1/N15,"") | K19: =IFERROR(1/N16,"") | L19: =IFERROR(1/N17,"") | M19: =IFERROR(1/N18,"") | N19: 1
B22: 2. Normalize matris ve yerel ağırlıklar
C23: G-47 İşletme Genel Bilgileri (kuruluş tarihçesi, coğrafi konum, büyüklük, ürün çeşidi) | D23: G-48 Ürün çeşitliliği | E23: G-49 Etik | F23: G-50 Çevre ve İklim Değişikliği Strateji Belgesi | G23: G-51 Çevre Mevzuatına Uyum | H23: G-52 İş Hukuku ve Sosyal Haklara Uyum | I23: G-53 İç Kontrol Sisteminin Etkinliği | J23: G-54 Stratejik Hedeflerde sürdürülebilirlik kriterleri | K23: G-55 Şeffaflık (Raporlama) | L23: G-56 Denetlenebilirlik | M23: G-57 İç Denetimin Bağımsızlık Düzeyi | N23: G-58 Sürdürülebilirlik Denetimi geçmişi | O23: Yerel ağırlık
B24: G-47 İşletme Genel Bilgileri (kuruluş tarihçesi, coğrafi konum, büyüklük, ürün çeşidi) | C24: =IFERROR(C8/C$36,"") | D24: =IFERROR(D8/D$36,"") | E24: =IFERROR(E8/E$36,"") | F24: =IFERROR(F8/F$36,"") | G24: =IFERROR(G8/G$36,"") | H24: =IFERROR(H8/H$36,"") | I24: =IFERROR(I8/I$36,"") | J24: =IFERROR(J8/J$36,"") | ... N24: =IFERROR(N8/N$36,"") | O24: =IFERROR(AVERAGE(C24:N24),"")
B25: G-48 Ürün çeşitliliği | C25: =IFERROR(C9/C$36,"") | D25: =IFERROR(D9/D$36,"") | E25: =IFERROR(E9/E$36,"") | F25: =IFERROR(F9/F$36,"") | G25: =IFERROR(G9/G$36,"") | H25: =IFERROR(H9/H$36,"") | I25: =IFERROR(I9/I$36,"") | J25: =IFERROR(J9/J$36,"") | ... N25: =IFERROR(N9/N$36,"") | O25: =IFERROR(AVERAGE(C25:N25),"")
B26: G-49 Etik | C26: =IFERROR(C10/C$36,"") | D26: =IFERROR(D10/D$36,"") | E26: =IFERROR(E10/E$36,"") | F26: =IFERROR(F10/F$36,"") | G26: =IFERROR(G10/G$36,"") | H26: =IFERROR(H10/H$36,"") | I26: =IFERROR(I10/I$36,"") | J26: =IFERROR(J10/J$36,"") | ... N26: =IFERROR(N10/N$36,"") | O26: =IFERROR(AVERAGE(C26:N26),"")
B27: G-50 Çevre ve İklim Değişikliği Strateji Belgesi | C27: =IFERROR(C11/C$36,"") | D27: =IFERROR(D11/D$36,"") | E27: =IFERROR(E11/E$36,"") | F27: =IFERROR(F11/F$36,"") | G27: =IFERROR(G11/G$36,"") | H27: =IFERROR(H11/H$36,"") | I27: =IFERROR(I11/I$36,"") | J27: =IFERROR(J11/J$36,"") | ... N27: =IFERROR(N11/N$36,"") | O27: =IFERROR(AVERAGE(C27:N27),"")
B28: G-51 Çevre Mevzuatına Uyum | C28: =IFERROR(C12/C$36,"") | D28: =IFERROR(D12/D$36,"") | E28: =IFERROR(E12/E$36,"") | F28: =IFERROR(F12/F$36,"") | G28: =IFERROR(G12/G$36,"") | H28: =IFERROR(H12/H$36,"") | I28: =IFERROR(I12/I$36,"") | J28: =IFERROR(J12/J$36,"") | ... N28: =IFERROR(N12/N$36,"") | O28: =IFERROR(AVERAGE(C28:N28),"")
B29: G-52 İş Hukuku ve Sosyal Haklara Uyum | C29: =IFERROR(C13/C$36,"") | D29: =IFERROR(D13/D$36,"") | E29: =IFERROR(E13/E$36,"") | F29: =IFERROR(F13/F$36,"") | G29: =IFERROR(G13/G$36,"") | H29: =IFERROR(H13/H$36,"") | I29: =IFERROR(I13/I$36,"") | J29: =IFERROR(J13/J$36,"") | ... N29: =IFERROR(N13/N$36,"") | O29: =IFERROR(AVERAGE(C29:N29),"")
B30: G-53 İç Kontrol Sisteminin Etkinliği | C30: =IFERROR(C14/C$36,"") | D30: =IFERROR(D14/D$36,"") | E30: =IFERROR(E14/E$36,"") | F30: =IFERROR(F14/F$36,"") | G30: =IFERROR(G14/G$36,"") | H30: =IFERROR(H14/H$36,"") | I30: =IFERROR(I14/I$36,"") | J30: =IFERROR(J14/J$36,"") | ... N30: =IFERROR(N14/N$36,"") | O30: =IFERROR(AVERAGE(C30:N30),"")
B31: G-54 Stratejik Hedeflerde sürdürülebilirlik kriterleri | C31: =IFERROR(C15/C$36,"") | D31: =IFERROR(D15/D$36,"") | E31: =IFERROR(E15/E$36,"") | F31: =IFERROR(F15/F$36,"") | G31: =IFERROR(G15/G$36,"") | H31: =IFERROR(H15/H$36,"") | I31: =IFERROR(I15/I$36,"") | J31: =IFERROR(J15/J$36,"") | ... N31: =IFERROR(N15/N$36,"") | O31: =IFERROR(AVERAGE(C31:N31),"")
B32: G-55 Şeffaflık (Raporlama) | C32: =IFERROR(C16/C$36,"") | D32: =IFERROR(D16/D$36,"") | E32: =IFERROR(E16/E$36,"") | F32: =IFERROR(F16/F$36,"") | G32: =IFERROR(G16/G$36,"") | H32: =IFERROR(H16/H$36,"") | I32: =IFERROR(I16/I$36,"") | J32: =IFERROR(J16/J$36,"") | ... N32: =IFERROR(N16/N$36,"") | O32: =IFERROR(AVERAGE(C32:N32),"")
B33: G-56 Denetlenebilirlik | C33: =IFERROR(C17/C$36,"") | D33: =IFERROR(D17/D$36,"") | E33: =IFERROR(E17/E$36,"") | F33: =IFERROR(F17/F$36,"") | G33: =IFERROR(G17/G$36,"") | H33: =IFERROR(H17/H$36,"") | I33: =IFERROR(I17/I$36,"") | J33: =IFERROR(J17/J$36,"") | ... N33: =IFERROR(N17/N$36,"") | O33: =IFERROR(AVERAGE(C33:N33),"")
B34: G-57 İç Denetimin Bağımsızlık Düzeyi | C34: =IFERROR(C18/C$36,"") | D34: =IFERROR(D18/D$36,"") | E34: =IFERROR(E18/E$36,"") | F34: =IFERROR(F18/F$36,"") | G34: =IFERROR(G18/G$36,"") | H34: =IFERROR(H18/H$36,"") | I34: =IFERROR(I18/I$36,"") | J34: =IFERROR(J18/J$36,"") | ... N34: =IFERROR(N18/N$36,"") | O34: =IFERROR(AVERAGE(C34:N34),"")
B35: G-58 Sürdürülebilirlik Denetimi geçmişi | C35: =IFERROR(C19/C$36,"") | D35: =IFERROR(D19/D$36,"") | E35: =IFERROR(E19/E$36,"") | F35: =IFERROR(F19/F$36,"") | G35: =IFERROR(G19/G$36,"") | H35: =IFERROR(H19/H$36,"") | I35: =IFERROR(I19/I$36,"") | J35: =IFERROR(J19/J$36,"") | ... N35: =IFERROR(N19/N$36,"") | O35: =IFERROR(AVERAGE(C35:N35),"")
B36: Sütun toplamı | C36: =SUM(C8:C19) | D36: =SUM(D8:D19) | E36: =SUM(E8:E19) | F36: =SUM(F8:F19) | G36: =SUM(G8:G19) | H36: =SUM(H8:H19) | I36: =SUM(I8:I19) | J36: =SUM(J8:J19) | ... N36: =SUM(N8:N19)
B38: Ağırlık toplamı | O38: =SUM(O24:O35)
B40: 3. Tutarlılık analizi
B41: λmax | O41: =C36*O24+D36*O25+E36*O26+F36*O27+G36*O28+H36*O29+I36*O30+J36*O31+K36*O32+L36*O33+M36*O34+N36*O35
B42: CI | O42: =IFERROR((O41-12)/(12-1),"")
B43: RI (n=12) | O43: 1.49
B44: CR | O44: =IFERROR(O42/O43,"")
B45: Karar | O45: =IF(COUNT(D8,E8,F8,G8,H8,I8,J8,K8,L8,M8,N8,E9,F9,G9,H9,I9,J9,K9,L9,M9,N9,F10,G10,H10,I10,J10,K10,L10,M10,N10,G11,H11,I11,J11,K11,L11,M11,N11,H12,I12,J12,K12,L12,M12,N12,I13,J13,K13,L13,M13,N13,J14,K14,L14,M14,N14,K15,L15,M15,N15,L16,M16,N16,M17,N17,N18)<66,"Veri bekleniyor",IF(O44<=0.1,"Tutarlı (CR ≤ 0,10)","Gözden geçirilmeli (CR > 0,10)"))

Sheet G_TedarikRisk
B2: Yönetişim → Tedarik Zinciri ve Risk Göstergeleri AHP
B4: Karşılaştırma düzeyi | C4: Yönetişim → Tedarik Zinciri ve Risk
B6: 1. İkili karşılaştırma matrisi – sarı hücrelere giriş yapınız
C7: G-59 Sertifikasyon (ISO, Global GAP, İTU, Helal Gıda vb.) | D7: G-60 Kalite Yönetim Sistemi | E7: G-61 Tedarikçi Coğrafi konumu (300 km) | F7: G-62 Tedarikçi Sürdürülebilirlik Kriterleri | G7: G-63 Paydaş Etki Ölçümü | H7: G-64 Veri Güvenliği ve Gizlilik | I7: G-65 Kurumsal Risk Yönetimi | K7: Giriş açıklaması
B8: G-59 Sertifikasyon (ISO, Global GAP, İTU, Helal Gıda vb.) | C8: 1 | D8: 2 | E8: 4 | F8: 4 | G8: 6 | H8: 3 | I8: 0.5 | K8: Sarı hücrelere Saaty ölçeğinde 1–9 veya ters değerleri giriniz. Yeşil hücreler otomatik ters değerlerdir.
B9: G-60 Kalite Yönetim Sistemi | C9: =IFERROR(1/D8,"") | D9: 1 | E9: 3 | F9: 3 | G9: 5 | H9: 2 | I9: 0.5
B10: G-61 Tedarikçi Coğrafi konumu (300 km) | C10: =IFERROR(1/E8,"") | D10: =IFERROR(1/E9,"") | E10: 1 | F10: 0.5 | G10: 3 | H10: =1/4 | I10: 0.25
B11: G-62 Tedarikçi Sürdürülebilirlik Kriterleri | C11: =IFERROR(1/F8,"") | D11: =IFERROR(1/F9,"") | E11: =IFERROR(1/F10,"") | F11: 1 | G11: 3 | H11: =1/4 | I11: =0.25
B12: G-63 Paydaş Etki Ölçümü | C12: =IFERROR(1/G8,"") | D12: =IFERROR(1/G9,"") | E12: =IFERROR(1/G10,"") | F12: =IFERROR(1/G11,"") | G12: 1 | H12: =1/7 | I12: =1/6
B13: G-64 Veri Güvenliği ve Gizlilik | C13: =IFERROR(1/H8,"") | D13: =IFERROR(1/H9,"") | E13: =IFERROR(1/H10,"") | F13: =IFERROR(1/H11,"") | G13: =IFERROR(1/H12,"") | H13: 1 | I13: 0.5
B14: G-65 Kurumsal Risk Yönetimi | C14: =IFERROR(1/I8,"") | D14: =IFERROR(1/I9,"") | E14: =IFERROR(1/I10,"") | F14: =IFERROR(1/I11,"") | G14: =IFERROR(1/I12,"") | H14: =IFERROR(1/I13,"") | I14: 1
B17: 2. Normalize matris ve yerel ağırlıklar
C18: G-59 Sertifikasyon (ISO, Global GAP, İTU, Helal Gıda vb.) | D18: G-60 Kalite Yönetim Sistemi | E18: G-61 Tedarikçi Coğrafi konumu (300 km) | F18: G-62 Tedarikçi Sürdürülebilirlik Kriterleri | G18: G-63 Paydaş Etki Ölçümü | H18: G-64 Veri Güvenliği ve Gizlilik | I18: G-65 Kurumsal Risk Yönetimi | J18: Yerel ağırlık
B19: G-59 Sertifikasyon (ISO, Global GAP, İTU, Helal Gıda vb.) | C19: =IFERROR(C8/C$26,"") | D19: =IFERROR(D8/D$26,"") | E19: =IFERROR(E8/E$26,"") | F19: =IFERROR(F8/F$26,"") | G19: =IFERROR(G8/G$26,"") | H19: =IFERROR(H8/H$26,"") | I19: =IFERROR(I8/I$26,"") | J19: =IFERROR(AVERAGE(C19:I19),"")
B20: G-60 Kalite Yönetim Sistemi | C20: =IFERROR(C9/C$26,"") | D20: =IFERROR(D9/D$26,"") | E20: =IFERROR(E9/E$26,"") | F20: =IFERROR(F9/F$26,"") | G20: =IFERROR(G9/G$26,"") | H20: =IFERROR(H9/H$26,"") | I20: =IFERROR(I9/I$26,"") | J20: =IFERROR(AVERAGE(C20:I20),"")
B21: G-61 Tedarikçi Coğrafi konumu (300 km) | C21: =IFERROR(C10/C$26,"") | D21: =IFERROR(D10/D$26,"") | E21: =IFERROR(E10/E$26,"") | F21: =IFERROR(F10/F$26,"") | G21: =IFERROR(G10/G$26,"") | H21: =IFERROR(H10/H$26,"") | I21: =IFERROR(I10/I$26,"") | J21: =IFERROR(AVERAGE(C21:I21),"")
B22: G-62 Tedarikçi Sürdürülebilirlik Kriterleri | C22: =IFERROR(C11/C$26,"") | D22: =IFERROR(D11/D$26,"") | E22: =IFERROR(E11/E$26,"") | F22: =IFERROR(F11/F$26,"") | G22: =IFERROR(G11/G$26,"") | H22: =IFERROR(H11/H$26,"") | I22: =IFERROR(I11/I$26,"") | J22: =IFERROR(AVERAGE(C22:I22),"")
B23: G-63 Paydaş Etki Ölçümü | C23: =IFERROR(C12/C$26,"") | D23: =IFERROR(D12/D$26,"") | E23: =IFERROR(E12/E$26,"") | F23: =IFERROR(F12/F$26,"") | G23: =IFERROR(G12/G$26,"") | H23: =IFERROR(H12/H$26,"") | I23: =IFERROR(I12/I$26,"") | J23: =IFERROR(AVERAGE(C23:I23),"")
B24: G-64 Veri Güvenliği ve Gizlilik | C24: =IFERROR(C13/C$26,"") | D24: =IFERROR(D13/D$26,"") | E24: =IFERROR(E13/E$26,"") | F24: =IFERROR(F13/F$26,"") | G24: =IFERROR(G13/G$26,"") | H24: =IFERROR(H13/H$26,"") | I24: =IFERROR(I13/I$26,"") | J24: =IFERROR(AVERAGE(C24:I24),"")
B25: G-65 Kurumsal Risk Yönetimi | C25: =IFERROR(C14/C$26,"") | D25: =IFERROR(D14/D$26,"") | E25: =IFERROR(E14/E$26,"") | F25: =IFERROR(F14/F$26,"") | G25: =IFERROR(G14/G$26,"") | H25: =IFERROR(H14/H$26,"") | I25: =IFERROR(I14/I$26,"") | J25: =IFERROR(AVERAGE(C25:I25),"")
B26: Sütun toplamı | C26: =SUM(C8:C14) | D26: =SUM(D8:D14) | E26: =SUM(E8:E14) | F26: =SUM(F8:F14) | G26: =SUM(G8:G14) | H26: =SUM(H8:H14) | I26: =SUM(I8:I14)
B28: Ağırlık toplamı | J28: =SUM(J19:J25)
B30: 3. Tutarlılık analizi
B31: λmax | J31: =C26*J19+D26*J20+E26*J21+F26*J22+G26*J23+H26*J24+I26*J25
B32: CI | J32: =IFERROR((J31-7)/(7-1),"")
B33: RI (n=7) | J33: 1.32
B34: CR | J34: =IFERROR(J32/J33,"")
B35: Karar | J35: =IF(COUNT(D8,E8,F8,G8,H8,I8,E9,F9,G9,H9,I9,F10,G10,H10,I10,G11,H11,I11,H12,I12,I13)<21,"Veri bekleniyor",IF(J34<=0.1,"Tutarlı (CR ≤ 0,10)","Gözden geçirilmeli (CR > 0,10)"))

Sheet FO_AltGruplar
B2: Finans ve Operasyon Ana Bloğu Alt Grupları AHP
B4: Karşılaştırma düzeyi | C4: Finans ve Operasyon ana bloğu alt grup karşılaştırması
B6: 1. İkili karşılaştırma matrisi – sarı hücrelere giriş yapınız
C7: Finansal | D7: Operasyonel | E7: Hayvancılık | F7: Bitkisel Üretim | H7: Giriş açıklaması
